Workbook

Sheet Data
A1: price | B1: area | C1: bedrooms | D1: bathrooms | E1: stories | F1: mainroad | G1: guestroom | H1: basement | I1: hotwaterheating | J1: airconditioning | K1: parking | L1: prefarea | M1: furnishingstatus
A2: 13300000 | B2: 7420 | C2: 4 | D2: 2 | E2: 3 | F2: yes | G2: no | H2: no | I2: no | J2: yes | K2: 2 | L2: yes | M2: furnished
A3: 12250000 | B3: 8960 | C3: 4 | D3: 4 | E3: 4 | F3: yes | G3: no | H3: no | I3: no | J3: yes | K3: 3 | L3: no | M3: furnished
A4: 12250000 | B4: 9960 | C4: 3 | D4: 2 | E4: 2 | F4: yes | G4: no | H4: yes | I4: no | J4: no | K4: 2 | L4: yes | M4: semi-furnished
A5: 12215000 | B5: 7500 | C5: 4 | D5: 2 | E5: 2 | F5: yes | G5: no | H5: yes | I5: no | J5: yes | K5: 3 | L5: yes | M5: furnished
A6: 11410000 | B6: 7420 | C6: 4 | D6: 1 | E6: 2 | F6: yes | G6: yes | H6: yes | I6: no | J6: yes | K6: 2 | L6: no | M6: furnished
A7: 10850000 | B7: 7500 | C7: 3 | D7: 3 | E7: 1 | F7: yes | G7: no | H7: yes | I7: no | J7: yes | K7: 2 | L7: yes | M7: semi-furnished
A8: 10150000 | B8: 8580 | C8: 4 | D8: 3 | E8: 4 | F8: yes | G8: no | H8: no | I8: no | J8: yes | K8: 2 | L8: yes | M8: semi-furnished
A9: 10150000 | B9: 16200 | C9: 5 | D9: 3 | E9: 2 | F9: yes | G9: no | H9: no | I9: no | J9: no | K9: 0 | L9: no | M9: unfurnished
A10: 9870000 | B10: 8100 | C10: 4 | D10: 1 | E10: 2 | F10: yes | G10: yes | H10: yes | I10: no | J10: yes | K10: 2 | L10: yes | M10: furnished
A11: 9800000 | B11: 5750 | C11: 3 | D11: 2 | E11: 4 | F11: yes | G11: yes | H11: no | I11: no | J11: yes | K11: 1 | L11: yes | M11: unfurnished
A12: 9800000 | B12: 13200 | C12: 3 | D12: 1 | E12: 2 | F12: yes | G12: no | H12: yes | I12: no | J12: yes | K12: 2 | L12: yes | M12: furnished
A13: 9681000 | B13: 6000 | C13: 4 | D13: 3 | E13: 2 | F13: yes | G13: yes | H13: yes | I13: yes | J13: no | K13: 2 | L13: no | M13: semi-furnished
... A546: 1750000 | B546: 3850 | C546: 3 | D546: 1 | E546: 2 | F546: yes | G546: no | H546: no | I546: no | J546: no | K546: 0 | L546: no | M546: unfurnished

Sheet Descriptive Statistics
A1: Variable | B1: Count | C1: Mean | D1: Median | E1: Std Dev | F1: Min | G1: Max | H1: Range
A2: Price | B2: =COUNT('[2]Raw Data'!A2:A546) -> 545 | C2: =AVERAGE(Data!A2:A546) -> 4766729.2 | D2: =MEDIAN(Data!A2:A546) -> 4340000 | E2: =STDEV(Data!A2:A546) -> 1870439.6 | F2: =MIN(Data!A2:A546) -> 1750000 | G2: =MAX(Data!A2:A546) -> 13300000 | H2: =G2-F2 -> 11550000
A3: Area | B3: =COUNT('[2]Raw Data'!B2:B546) -> 545 | C3: =AVERAGE(Data!B2:B546) -> 5150.5413 | D3: =MEDIAN(Data!B2:B546) -> 4600 | E3: =STDEV(Data!B2:B546) -> 2170.141 | F3: =MIN(Data!B2:B546) -> 1650 | G3: =MAX(Data!B2:B546) -> 16200 | H3: =G3-F3 -> 14550
A4: Bedrooms | B4: =COUNT('[2]Raw Data'!C2:C546) -> 545 | C4: =AVERAGE(Data!C2:C546) -> 2.9651376 | D4: =MEDIAN(Data!C2:C546) -> 3 | E4: =STDEV(Data!C2:C546) -> 0.73806386 | F4: =MIN(Data!C2:C546) -> 1 | G4: =MAX(Data!C2:C546) -> 6 | H4: =G4-F4 -> 5
A5: Bathrooms | B5: =COUNT('[2]Raw Data'!D2:D546) -> 545 | C5: =AVERAGE(Data!D2:D546) -> 1.2862385 | D5: =MEDIAN(Data!D2:D546) -> 1 | E5: =STDEV(Data!D2:D546) -> 0.50246962 | F5: =MIN(Data!D2:D546) -> 1 | G5: =MAX(Data!D2:D546) -> 4 | H5: =G5-F5 -> 3
A6: Stories | B6: =COUNT('[2]Raw Data'!E2:E546) -> 545 | C6: =AVERAGE(Data!E2:E546) -> 1.8055046 | D6: =MEDIAN(Data!E2:E546) -> 2 | E6: =STDEV(Data!E2:E546) -> 0.86749246 | F6: =MIN(Data!E2:E546) -> 1 | G6: =MAX(Data!E2:E546) -> 4 | H6: =G6-F6 -> 3
A7: Parking | B7: =COUNT('[2]Raw Data'!K2:K546) -> 545 | C7: =AVERAGE(Data!K2:K546) -> 0.69357798 | D7: =MEDIAN(Data!K2:K546) -> 0 | E7: =STDEV(Data!K2:K546) -> 0.86158575 | F7: =MIN(Data!K2:K546) -> 0 | G7: =MAX(Data!K2:K546) -> 3 | H7: =G7-F7 -> 3
A9: Variable | B9: Count | C9: Mode | D9: Unique Categories
A10: Mainroad | B10: =COUNTA(Data!F2:F546) -> 545 | C10: Yes | D10: 2
A11: Guestroom | B11: =COUNTA(Data!G2:G546) -> 545 | C11: No | D11: 2
A12: Basement | B12: =COUNTA(Data!H2:H546) -> 545 | C12: Yes | D12: 2
A13: HotWaterHeating | B13: =COUNTA(Data!I2:I546) -> 545 | C13: No | D13: 2
A14: AirConditioning | B14: =COUNTA(Data!J2:J546) -> 545 | C14: No | D14: 2
A15: PrefArea | B15: =COUNTA(Data!L2:L546) -> 545 | C15: No | D15: 2
A16: FurnishingStatus | B16: =COUNTA(Data!M2:M546) -> 545 | C16: Semi-Furnished | D16: 3

Sheet Frequency Tables
B2: Main Road Frequency | E2: Relative Frequency
B3: Row Labels | C3: Count of mainroad | E3: Row Labels | F3: Count of mainroad
B4: yes | C4: 468 | E4: yes | F4: 0.8587156
B5: no | C5: 77 | E5: no | F5: 0.1412844
B6: Grand Total | C6: 545 | E6: Grand Total | F6: 1 | G6: A vast majority of rodes (over 85%) have access to a main road.
B8: Guestroom Frequency | E8: Relative Frequency
B9: Row Labels | C9: Count of guestroom | E9: Row Labels | F9: Count of guestroom
B10: yes | C10: 97 | E10: yes | F10: 0.17798165
B11: no | C11: 448 | E11: no | F11: 0.82201835
B12: Grand Total | C12: 545 | E12: Grand Total | F12: 1 | G12: Very few homes have a guest room.
B14: Basement Frequency | E14: Relative Frequency
B15: Row Labels | C15: Count of basement | E15: Row Labels | F15: Count of basement
B16: yes | C16: 191 | E16: yes | F16: 0.35045872
B17: no | C17: 354 | E17: no | F17: 0.64954128
B18: Grand Total | C18: 545 | E18: Grand Total | F18: 1 | G18: Almost 2/3rds of homes have a basement.
B20: Hotwaterheating Frequency | E20: Relative Frequency
B21: Row Labels | C21: Count of hotwaterheating | E21: Row Labels | F21: Count of hotwaterheating
B22: no | C22: 520 | E22: no | F22: 0.95412844
B23: yes | C23: 25 | E23: yes | F23: 0.04587156
B24: Grand Total | C24: 545 | E24: Grand Total | F24: 1 | G24: Less than 5% of homes have hot water.
B26: Aircondidtioning Frequency | E26: Relative Frequency
B27: Row Labels | C27: Count of airconditioning | E27: Row Labels | F27: Count of airconditioning
B28: no | C28: 373 | E28: no | F28: 0.68440367
B29: yes | C29: 172 | E29: yes | F29: 0.31559633
B30: Grand Total | C30: 545 | E30: Grand Total | F30: 1 | G30: Almost 70% of homes do not have air conditioning
B32: Prefarea Frequency | E32: Relative Frequency
B33: Row Labels | C33: Count of prefarea | E33: Row Labels | F33: Count of prefarea
B34: no | C34: 417 | E34: no | F34: 0.76513761
B35: yes | C35: 128 | E35: yes | F35: 0.23486239
B36: Grand Total | C36: 545 | E36: Grand Total | F36: 1 | G36: 3/4rds of homes are not located in a preferred area
B38: Furnishing Status Frequency | E38: Relative Frequency
B39: Row Labels | C39: Count of furnishingstatus | E39: Row Labels | F39: Count of furnishingstatus
B40: furnished | C40: 140 | E40: furnished | F40: 0.25688073
B41: semi-furnished | C41: 227 | E41: semi-furnished | F41: 0.41651376
B42: unfurnished | C42: 178 | E42: unfurnished | F42: 0.3266055
B43: Grand Total | C43: 545 | E43: Grand Total | F43: 1 | G43: Furnishing status is almost evenly split into thirds, with semi-furnished being the plurality.

Sheet Data Visualizations
K42: Row Labels | L42: Count of bedrooms
K43: 1 | L43: 2
K44: 2 | L44: 136
K45: 3 | L45: 300
K46: 4 | L46: 95
K47: 5 | L47: 10
K48: 6 | L48: 2
K49: Grand Total | L49: 545
K58: Row Labels | L58: Count of bathrooms
K59: 1 | L59: 401
K60: 2 | L60: 133
K61: 3 | L61: 10
K62: 4 | L62: 1
K63: Grand Total | L63: 545
K74: Row Labels | L74: Count of stories
K75: 1 | L75: 227
K76: 2 | L76: 238
K77: 3 | L77: 39
K78: 4 | L78: 41
K79: Grand Total | L79: 545
K90: Row Labels | L90: Count of parking
K91: 0 | L91: 299
K92: 1 | L92: 126
K93: 2 | L93: 108
K94: 3 | L94: 12
K95: Grand Total | L95: 545
K106: Row Labels | L106: Count of mainroad
K107: no | L107: 77
K108: yes | L108: 468
K109: Grand Total | L109: 545
K121: Row Labels | L121: Count of guestroom
K122: no | L122: 448
K123: yes | L123: 97
K124: Grand Total | L124: 545
L138: Count of basement
K139: no | L139: 354
K140: yes | L140: 191
K141: Grand Total | L141: 545
L154: Count of hotwaterheating
K155: no | L155: 520
...

Sheet Commentary
A1: Across all entries, the data was clean with no missing values or duplicates.
A2: Price and area turned out to be the most important continuous variables, as both have the widest spread relative to their averages,
A3: and their matching right-skewed shape on our visualizations suggests area is a majordriver of higher prices.
A4: The categorical data showed an imbalance: main road access (86%) and hot water heating (under 5% "yes") sit at extremes.
A5: Airconditioning is only present in almost 30% of homes, meaning it could easily impact home price without the bias of the previous two features.
A6: Basements are absent in 64% of homes, and only 23% of houses are located in preferred areas.
A7: Furnishing status is the only variable that is almost evenly split, with approximately a third of homes in each category.
A8: The number of bedrooms and stories, however, do not show a clean relationship with price, as seen on our scatter plots.
A9: Taken together, area, bathrooms, and air conditioning stand out as the strongest candidate variables for further exploration.
